<?xml version="1.0" encoding="UTF-8"?>
<!-- Generated by org.testng.reporters.JUnitReportReporter -->
<testsuite skipped="1" hostname="HIBAIL56180" name="org.TestngAttributes" tests="20" failures="0" timestamp="05 Sep 2017 13:50:11 GMT" time="4.526" errors="2">
  <testcase name="test1" time="0.030" classname="org.TestngAttributes"/>
  <testcase name="test9" time="0.091" classname="org.TestngAttributes"/>
  <testcase name="test5" time="0.003" classname="org.TestngAttributes"/>
  <testcase name="test9" time="0.011" classname="org.TestngAttributes"/>
  <testcase name="test9" time="0.160" classname="org.TestngAttributes"/>
  <testcase name="test2" time="0.001" classname="org.TestngAttributes"/>
  <testcase name="test7" time="0.008" classname="org.TestngAttributes"/>
  <testcase name="test9" time="0.000" classname="org.TestngAttributes"/>
  <testcase name="test9" time="0.071" classname="org.TestngAttributes"/>
  <testcase name="test9" time="0.000" classname="org.TestngAttributes"/>
  <testcase name="test3" time="0.000" classname="org.TestngAttributes"/>
  <testcase name="test9" time="0.000" classname="org.TestngAttributes"/>
  <testcase name="test4" time="0.005" classname="org.TestngAttributes"/>
  <testcase name="test6" time="2.093" classname="org.TestngAttributes">
    <error type="java.lang.ArrayIndexOutOfBoundsException" message="0">
      <![CDATA[java.lang.ArrayIndexOutOfBoundsException: 0
	at org.testng.internal.MethodInvocationHelper.invokeWithTimeoutWithNewExecutor(MethodInvocationHelper.java:289)
	at org.testng.internal.MethodInvocationHelper.invokeWithTimeout(MethodInvocationHelper.java:246)
	at org.testng.internal.Invoker.invokeMethod(Invoker.java:667)
	at org.testng.internal.Invoker.invokeTestMethod(Invoker.java:869)
	at org.testng.internal.Invoker.invokeTestMethods(Invoker.java:1193)
	at org.testng.internal.TestMethodWorker.invokeTestMethods(TestMethodWorker.java:126)
	at org.testng.internal.TestMethodWorker.run(TestMethodWorker.java:109)
	at org.testng.TestRunner.privateRun(TestRunner.java:744)
	at org.testng.TestRunner.run(TestRunner.java:602)
	at org.testng.SuiteRunner.runTest(SuiteRunner.java:380)
	at org.testng.SuiteRunner.runSequentially(SuiteRunner.java:375)
	at org.testng.SuiteRunner.privateRun(SuiteRunner.java:340)
	at org.testng.SuiteRunner.run(SuiteRunner.java:289)
	at org.testng.SuiteRunnerWorker.runSuite(SuiteRunnerWorker.java:52)
	at org.testng.SuiteRunnerWorker.run(SuiteRunnerWorker.java:86)
	at org.testng.TestNG.runSuitesSequentially(TestNG.java:1301)
	at org.testng.TestNG.runSuitesLocally(TestNG.java:1226)
	at org.testng.TestNG.runSuites(TestNG.java:1144)
	at org.testng.TestNG.run(TestNG.java:1115)
	at org.testng.remote.AbstractRemoteTestNG.run(AbstractRemoteTestNG.java:132)
	at org.testng.remote.RemoteTestNG.initAndRun(RemoteTestNG.java:230)
	at org.testng.remote.RemoteTestNG.main(RemoteTestNG.java:76)
]]>
    </error>
  </testcase> <!-- test6 -->
  <testcase name="test9" time="0.031" classname="org.TestngAttributes"/>
  <testcase name="test8" time="2.010" classname="org.TestngAttributes">
    <error type="java.lang.ArrayIndexOutOfBoundsException" message="0">
      <![CDATA[java.lang.ArrayIndexOutOfBoundsException: 0
	at org.testng.internal.MethodInvocationHelper.invokeWithTimeoutWithNewExecutor(MethodInvocationHelper.java:289)
	at org.testng.internal.MethodInvocationHelper.invokeWithTimeout(MethodInvocationHelper.java:246)
	at org.testng.internal.Invoker.invokeMethod(Invoker.java:667)
	at org.testng.internal.Invoker.invokeTestMethod(Invoker.java:869)
	at org.testng.internal.Invoker.invokeTestMethods(Invoker.java:1193)
	at org.testng.internal.TestMethodWorker.invokeTestMethods(TestMethodWorker.java:126)
	at org.testng.internal.TestMethodWorker.run(TestMethodWorker.java:109)
	at org.testng.TestRunner.privateRun(TestRunner.java:744)
	at org.testng.TestRunner.run(TestRunner.java:602)
	at org.testng.SuiteRunner.runTest(SuiteRunner.java:380)
	at org.testng.SuiteRunner.runSequentially(SuiteRunner.java:375)
	at org.testng.SuiteRunner.privateRun(SuiteRunner.java:340)
	at org.testng.SuiteRunner.run(SuiteRunner.java:289)
	at org.testng.SuiteRunnerWorker.runSuite(SuiteRunnerWorker.java:52)
	at org.testng.SuiteRunnerWorker.run(SuiteRunnerWorker.java:86)
	at org.testng.TestNG.runSuitesSequentially(TestNG.java:1301)
	at org.testng.TestNG.runSuitesLocally(TestNG.java:1226)
	at org.testng.TestNG.runSuites(TestNG.java:1144)
	at org.testng.TestNG.run(TestNG.java:1115)
	at org.testng.remote.AbstractRemoteTestNG.run(AbstractRemoteTestNG.java:132)
	at org.testng.remote.RemoteTestNG.initAndRun(RemoteTestNG.java:230)
	at org.testng.remote.RemoteTestNG.main(RemoteTestNG.java:76)
]]>
    </error>
  </testcase> <!-- test8 -->
  <testcase name="test9" time="0.000" classname="org.TestngAttributes"/>
  <testcase name="test9" time="0.010" classname="org.TestngAttributes"/>
  <testcase name="test5" time="0.002" classname="org.TestngAttributes"/>
  <testcase name="test41" classname="org.TestngAttributes">
    <skipped/>
  </testcase> <!-- test41 -->
</testsuite> <!-- org.TestngAttributes -->
